Workbook

Sheet Оригинал
A1: Модель аппарата | B1: Производитель | C1: Тип расходки | D1: Цвет | E1: Артикул | F1: Ресурс стр. | G1: Цена | H1: Примечание | I1: № в подборе
A2: Xerox WorkCentre 5330 | B2: Xerox | C2: Тонер-картридж | D2: Black | E2: 006R01160 | I2: =IF(AND($A2<>"",$A2=Подбор!$C$4),MAX(I$1:I1)+1,"")
A3: Xerox WorkCentre 5330 | B3: Xerox | C3: Драм-юнит | D3: — | E3: 013R00591 | I3: =IF(AND($A3<>"",$A3=Подбор!$C$4),MAX(I$1:I2)+1,"")
A4: Xerox WorkCentre 5330 | B4: Xerox | C4: Термоузел | D4: — | E4: 126K29403 | I4: =IF(AND($A4<>"",$A4=Подбор!$C$4),MAX(I$1:I3)+1,"")
A5: Xerox WorkCentre 7845 | B5: Xerox | C5: Тонер-картридж | D5: Black | E5: 006R01517 | F5: 26000 | I5: =IF(AND($A5<>"",$A5=Подбор!$C$4),MAX(I$1:I4)+1,"") -> 1
A6: Xerox WorkCentre 7845 | B6: Xerox | C6: Тонер-картридж | D6: Cyan | E6: 006R01520 | F6: 15000 | I6: =IF(AND($A6<>"",$A6=Подбор!$C$4),MAX(I$1:I5)+1,"") -> 2
A7: Xerox WorkCentre 7845 | B7: Xerox | C7: Тонер-картридж | D7: Magenta | E7: 006R01519 | F7: 15000 | I7: =IF(AND($A7<>"",$A7=Подбор!$C$4),MAX(I$1:I6)+1,"") -> 3
A8: Xerox WorkCentre 7845 | B8: Xerox | C8: Тонер-картридж | D8: Yellow | E8: 006R01518 | F8: 15000 | I8: =IF(AND($A8<>"",$A8=Подбор!$C$4),MAX(I$1:I7)+1,"") -> 4
A9: Xerox WorkCentre 7845 | B9: Xerox | C9: Драм-юнит | D9: — | E9: 013R00662 | F9: 125000 | I9: =IF(AND($A9<>"",$A9=Подбор!$C$4),MAX(I$1:I8)+1,"") -> 5
A10: Xerox WorkCentre 7845 | B10: Xerox | C10: Блок проявки | D10: — | E10: 848K65672 | I10: =IF(AND($A10<>"",$A10=Подбор!$C$4),MAX(I$1:I9)+1,"") -> 6
A11: Xerox WorkCentre 7845 | B11: Xerox | C11: Бункер отработки | D11: — | E11: 008R13061 | I11: =IF(AND($A11<>"",$A11=Подбор!$C$4),MAX(I$1:I10)+1,"") -> 7
A12: Xerox WorkCentre 7845 | B12: Xerox | C12: Термоузел | D12: — | E12: 604K62230 | I12: =IF(AND($A12<>"",$A12=Подбор!$C$4),MAX(I$1:I11)+1,"") -> 8
A13: Pantum BM5100ADN | B13: Pantum | C13: Тонер-картридж | D13: Black | E13: TL-5120X | F13: 6000 | I13: =IF(AND($A13<>"",$A13=Подбор!$C$4),MAX(I$1:I12)+1,"")
A14: Pantum BM5100ADN | B14: Pantum | C14: Драм-картридж | D14: — | E14: DL-5120 | F14: 30000 | I14: =IF(AND($A14<>"",$A14=Подбор!$C$4),MAX(I$1:I13)+1,"")
A15: Pantum BM5100ADN | B15: Pantum | C15: Бункер отработки | D15: — | E15: CWT-2000 | I15: =IF(AND($A15<>"",$A15=Подбор!$C$4),MAX(I$1:I14)+1,"")
A16: Pantum BM5100ADN | B16: Pantum | C16: Термоузел | D16: — | E16: 302111018801 | I16: =IF(AND($A16<>"",$A16=Подбор!$C$4),MAX(I$1:I15)+1,"")
A17: Konica Minolta bizhub C257i | B17: Konica Minolta | C17: Тонер-картридж | D17: Black | E17: TN-328K | F17: 28000 | I17: =IF(AND($A17<>"",$A17=Подбор!$C$4),MAX(I$1:I16)+1,"")
A18: Konica Minolta bizhub C257i | B18: Konica Minolta | C18: Тонер-картридж | D18: Cyan | E18: TN-328C | F18: 28000 | I18: =IF(AND($A18<>"",$A18=Подбор!$C$4),MAX(I$1:I17)+1,"")
A19: Konica Minolta bizhub C257i | B19: Konica Minolta | C19: Тонер-картридж | D19: Magenta | E19: TN-328M | F19: 28000 | I19: =IF(AND($A19<>"",$A19=Подбор!$C$4),MAX(I$1:I18)+1,"")
A20: Konica Minolta bizhub C257i | B20: Konica Minolta | C20: Тонер-картридж | D20: Yellow | E20: TN-328Y | F20: 28000 | I20: =IF(AND($A20<>"",$A20=Подбор!$C$4),MAX(I$1:I19)+1,"")
A21: Konica Minolta bizhub C257i | B21: Konica Minolta | C21: Драм-юнит | D21: — | E21: DR-316K (AAV70RD) | I21: =IF(AND($A21<>"",$A21=Подбор!$C$4),MAX(I$1:I20)+1,"")
A22: Lexmark MX510de | B22: Lexmark | C22: Тонер-картридж | D22: Black | E22: 60F5H0E | F22: 10000 | I22: =IF(AND($A22<>"",$A22=Подбор!$C$4),MAX(I$1:I21)+1,"")
A23: Lexmark MX510de | B23: Lexmark | C23: Драм-юнит | D23: — | E23: 50F0Z00 | F23: 60000 | I23: =IF(AND($A23<>"",$A23=Подбор!$C$4),MAX(I$1:I22)+1,"")
A24: Sharp BP-30M28 | B24: Sharp | C24: Тонер-картридж | D24: Black | E24: BPGT300 | F24: 18000 | I24: =IF(AND($A24<>"",$A24=Подбор!$C$4),MAX(I$1:I23)+1,"")
A25: Sharp BP-30M28 | B25: Sharp | C25: Драм-юнит | D25: — | E25: MX36GRSA | I25: =IF(AND($A25<>"",$A25=Подбор!$C$4),MAX(I$1:I24)+1,"")
A26: Sharp BP-30M28 | B26: Sharp | C26: Бункер отработки | D26: — | E26: MX230HB | I26: =IF(AND($A26<>"",$A26=Подбор!$C$4),MAX(I$1:I25)+1,"")
A27: Sharp BP-30M28 | B27: Sharp | C27: Термоузел | D27: — | E27: BPFU201 | I27: =IF(AND($A27<>"",$A27=Подбор!$C$4),MAX(I$1:I26)+1,"")
A28: HP LaserJet Pro MFP M428fdn | B28: HP | C28: Тонер-картридж | D28: Black | E28: CF258A (58A) | F28: 3000 | I28: =IF(AND($A28<>"",$A28=Подбор!$C$4),MAX(I$1:I27)+1,"")
A29: HP LaserJet Pro MFP M428fdn | B29: HP | C29: Драм-юнит | D29: — | E29: CF219A | F29: 23000 | I29: =IF(AND($A29<>"",$A29=Подбор!$C$4),MAX(I$1:I28)+1,"")
A30: HP LaserJet Pro MFP M428fdn | B30: HP | C30: Термоузел | D30: — | E30: RM2-5425 | I30: =IF(AND($A30<>"",$A30=Подбор!$C$4),MAX(I$1:I29)+1,"")
A31: Toshiba e-STUDIO2505 | B31: Toshiba | C31: Тонер-картридж | D31: Black | E31: T-2505E | F31: 15000 | I31: =IF(AND($A31<>"",$A31=Подбор!$C$4),MAX(I$1:I30)+1,"")
A32: Toshiba e-STUDIO2505 | B32: Toshiba | C32: Драм-юнит | D32: — | E32: OD-2505 | I32: =IF(AND($A32<>"",$A32=Подбор!$C$4),MAX(I$1:I31)+1,"")
A33: Toshiba e-STUDIO2505 | B33: Toshiba | C33: Девелопер | D33: — | E33: 6LJ83445000 | I33: =IF(AND($A33<>"",$A33=Подбор!$C$4),MAX(I$1:I32)+1,"")
A34: Kyocera TASKalfa 6500i | B34: Kyocera | C34: Тонер-картридж | D34: Black | E34: TK-6705 | F34: 55000 | I34: =IF(AND($A34<>"",$A34=Подбор!$C$4),MAX(I$1:I33)+1,"")
A35: Kyocera TASKalfa 6500i | B35: Kyocera | C35: Драм-юнит | D35: — | E35: DK-6705 | I35: =IF(AND($A35<>"",$A35=Подбор!$C$4),MAX(I$1:I34)+1,"")
A36: Kyocera TASKalfa 6500i | B36: Kyocera | C36: Блок проявки | D36: — | E36: DV-6705 | I36: =IF(AND($A36<>"",$A36=Подбор!$C$4),MAX(I$1:I35)+1,"")
A37: Kyocera TASKalfa 6500i | B37: Kyocera | C37: Бункер отработки | D37: — | E37: WT-861 | I37: =IF(AND($A37<>"",$A37=Подбор!$C$4),MAX(I$1:I36)+1,"")
A38: Kyocera TASKalfa 6500i | B38: Kyocera | C38: Термоузел | D38: — | E38: FK-6707 | I38: =IF(AND($A38<>"",$A38=Подбор!$C$4),MAX(I$1:I37)+1,"")
A39: Xerox Phaser 5550DN | B39: Xerox | C39: Тонер-картридж | D39: Black | E39: 113R00668 | F39: 35000 | I39: =IF(AND($A39<>"",$A39=Подбор!$C$4),MAX(I$1:I38)+1,"")
A40: Xerox Phaser 5550DN | B40: Xerox | C40: Драм-юнит | D40: — | E40: 113R00670 | I40: =IF(AND($A40<>"",$A40=Подбор!$C$4),MAX(I$1:I39)+1,"")
...

Sheet Совместимая
A1: Модель аппарата | B1: Производитель | C1: Тип расходки | D1: Цвет | E1: Артикул | F1: Бренд | G1: Ресурс стр. | H1: Цена | I1: Примечание | J1: № в подборе
A2: Xerox WorkCentre 5330 | B2: Xerox | C2: Тонер-картридж | D2: Black | E2: CS-WC5325 | F2: Cactus | J2: =IF(AND($A2<>"",$A2=Подбор!$C$4),MAX(J$1:J1)+1,"")
A3: Xerox WorkCentre 5330 | B3: Xerox | C3: Драм-юнит | D3: — | E3: CS-WC5325X | F3: Cactus | J3: =IF(AND($A3<>"",$A3=Подбор!$C$4),MAX(J$1:J2)+1,"")
A4: Xerox WorkCentre 5330 | B4: Xerox | C4: Термоузел | D4: — | E4: CS-FU-XER-WC5330 | F4: Cactus | J4: =IF(AND($A4<>"",$A4=Подбор!$C$4),MAX(J$1:J3)+1,"")
A5: Xerox WorkCentre 7845 | B5: Xerox | C5: Тонер-картридж | D5: Black | E5: CS-WC7525BK | F5: Cactus | J5: =IF(AND($A5<>"",$A5=Подбор!$C$4),MAX(J$1:J4)+1,"") -> 1
A6: Xerox WorkCentre 7845 | B6: Xerox | C6: Тонер-картридж | D6: Cyan | E6: CS-WC7525C | F6: Cactus | J6: =IF(AND($A6<>"",$A6=Подбор!$C$4),MAX(J$1:J5)+1,"") -> 2
A7: Xerox WorkCentre 7845 | B7: Xerox | C7: Тонер-картридж | D7: Magenta | E7: CS-WC7525M | F7: Cactus | J7: =IF(AND($A7<>"",$A7=Подбор!$C$4),MAX(J$1:J6)+1,"") -> 3
A8: Xerox WorkCentre 7845 | B8: Xerox | C8: Тонер-картридж | D8: Yellow | E8: CS-WC7525Y | F8: Cactus | J8: =IF(AND($A8<>"",$A8=Подбор!$C$4),MAX(J$1:J7)+1,"") -> 4
A9: Xerox WorkCentre 7845 | B9: Xerox | C9: Драм-юнит | D9: — | E9: CS-DU7525 | F9: Cactus | J9: =IF(AND($A9<>"",$A9=Подбор!$C$4),MAX(J$1:J8)+1,"") -> 5
A10: Xerox WorkCentre 7845 | B10: Xerox | C10: Блок проявки | D10: — | E10: CS-DU7525RU | F10: Cactus | J10: =IF(AND($A10<>"",$A10=Подбор!$C$4),MAX(J$1:J9)+1,"") -> 6
A11: Xerox WorkCentre 7845 | B11: Xerox | C11: Бункер отработки | D11: — | E11: CS-WB7425 | F11: Cactus | J11: =IF(AND($A11<>"",$A11=Подбор!$C$4),MAX(J$1:J10)+1,"") -> 7
A12: Xerox WorkCentre 7845 | B12: Xerox | C12: Термоузел | D12: — | E12: CS-FU-XER-WC7545 | F12: Cactus | J12: =IF(AND($A12<>"",$A12=Подбор!$C$4),MAX(J$1:J11)+1,"") -> 8
A13: Pantum BM5100ADN | B13: Pantum | C13: Тонер-картридж | D13: Black | E13: CS-TL-5120X | F13: Cactus | G13: 6000 | I13: Ресурс по оригиналу — уточнить | J13: =IF(AND($A13<>"",$A13=Подбор!$C$4),MAX(J$1:J12)+1,"")
A14: Pantum BM5100ADN | B14: Pantum | C14: Тонер-картридж | D14: Black | E14: GG-TL5120X | F14: G&G | G14: 6000 | I14: Ресурс по оригиналу — уточнить | J14: =IF(AND($A14<>"",$A14=Подбор!$C$4),MAX(J$1:J13)+1,"")
A15: Pantum BM5100ADN | B15: Pantum | C15: Драм-картридж | D15: — | E15: CS-DL-5120 | F15: Cactus | G15: 30000 | I15: Ресурс по оригиналу — уточнить | J15: =IF(AND($A15<>"",$A15=Подбор!$C$4),MAX(J$1:J14)+1,"")
A16: Pantum BM5100ADN | B16: Pantum | C16: Драм-картридж | D16: — | E16: GG-DL5120 | F16: G&G | G16: 30000 | I16: Ресурс по оригиналу — уточнить | J16: =IF(AND($A16<>"",$A16=Подбор!$C$4),MAX(J$1:J15)+1,"")
A17: Pantum BM5100ADN | B17: Pantum | C17: Драм-картридж | D17: — | E17: HB-DL-5120 | F17: HiBlack | G17: 30000 | I17: Ресурс по оригиналу — уточнить | J17: =IF(AND($A17<>"",$A17=Подбор!$C$4),MAX(J$1:J16)+1,"")
A18: Pantum BM5100ADN | B18: Pantum | C18: Драм-картридж | D18: — | E18: NV-DL-5120 | F18: NV-Print | G18: 30000 | I18: Ресурс по оригиналу — уточнить | J18: =IF(AND($A18<>"",$A18=Подбор!$C$4),MAX(J$1:J17)+1,"")
A19: Pantum BM5100ADN | B19: Pantum | C19: Термоузел | D19: — | E19: — | J19: =IF(AND($A19<>"",$A19=Подбор!$C$4),MAX(J$1:J18)+1,"")
A20: Konica Minolta bizhub C257i | B20: Konica Minolta | C20: Тонер-картридж | D20: Black | E20: CS-TN512K | F20: Cactus | G20: 30000 | I20: Ресурс по оригиналу — уточнить | J20: =IF(AND($A20<>"",$A20=Подбор!$C$4),MAX(J$1:J19)+1,"")
A21: Konica Minolta bizhub C257i | B21: Konica Minolta | C21: Тонер-картридж | D21: Cyan | E21: CS-TN512C | F21: Cactus | J21: =IF(AND($A21<>"",$A21=Подбор!$C$4),MAX(J$1:J20)+1,"")
A22: Konica Minolta bizhub C257i | B22: Konica Minolta | C22: Тонер-картридж | D22: Magenta | E22: CS-TN512M | F22: Cactus | J22: =IF(AND($A22<>"",$A22=Подбор!$C$4),MAX(J$1:J21)+1,"")
A23: Konica Minolta bizhub C257i | B23: Konica Minolta | C23: Тонер-картридж | D23: Yellow | E23: CS-TN512Y | F23: Cactus | J23: =IF(AND($A23<>"",$A23=Подбор!$C$4),MAX(J$1:J22)+1,"")
A24: Konica Minolta bizhub C257i | B24: Konica Minolta | C24: Драм-юнит | D24: — | E24: AAV70RD | J24: =IF(AND($A24<>"",$A24=Подбор!$C$4),MAX(J$1:J23)+1,"")
A25: Lexmark MX510de | B25: Lexmark | C25: Тонер-картридж | D25: Black | E25: GG-56F5U00 | F25: G&G | J25: =IF(AND($A25<>"",$A25=Подбор!$C$4),MAX(J$1:J24)+1,"")
A26: Lexmark MX510de | B26: Lexmark | C26: Тонер-картридж | D26: Black | E26: NV-56F5U0ENC | F26: NV-Print | J26: =IF(AND($A26<>"",$A26=Подбор!$C$4),MAX(J$1:J25)+1,"")
A27: Lexmark MX510de | B27: Lexmark | C27: Драм-юнит | D27: — | E27: SFR-56F0Z00 | F27: SuperFine | G27: 60000 | I27: Ресурс по оригиналу — уточнить | J27: =IF(AND($A27<>"",$A27=Подбор!$C$4),MAX(J$1:J26)+1,"")
A28: Sharp BP-30M28 | B28: Sharp | C28: Тонер-картридж | D28: Black | E28: — | J28: =IF(AND($A28<>"",$A28=Подбор!$C$4),MAX(J$1:J27)+1,"")
A29: Sharp BP-30M28 | B29: Sharp | C29: Драм-юнит | D29: — | E29: — | J29: =IF(AND($A29<>"",$A29=Подбор!$C$4),MAX(J$1:J28)+1,"")
A30: Sharp BP-30M28 | B30: Sharp | C30: Бункер отработки | D30: — | E30: — | J30: =IF(AND($A30<>"",$A30=Подбор!$C$4),MAX(J$1:J29)+1,"")
A31: Sharp BP-30M28 | B31: Sharp | C31: Термоузел | D31: — | E31: — | J31: =IF(AND($A31<>"",$A31=Подбор!$C$4),MAX(J$1:J30)+1,"")
A32: HP LaserJet Pro MFP M428fdn | B32: HP | C32: Тонер-картридж | D32: Black | E32: CSP-CF259X | F32: Cactus | J32: =IF(AND($A32<>"",$A32=Подбор!$C$4),MAX(J$1:J31)+1,"")
A33: HP LaserJet Pro MFP M428fdn | B33: HP | C33: Тонер-картридж | D33: Black | E33: HB-CF259X | F33: HiBlack | J33: =IF(AND($A33<>"",$A33=Подбор!$C$4),MAX(J$1:J32)+1,"")
A34: HP LaserJet Pro MFP M428fdn | B34: HP | C34: Тонер-картридж | D34: Black | E34: GG-CF259X | F34: G&G | J34: =IF(AND($A34<>"",$A34=Подбор!$C$4),MAX(J$1:J33)+1,"")
A35: HP LaserJet Pro MFP M428fdn | B35: HP | C35: Драм-юнит | D35: — | E35: CS-CF219A | F35: Cactus | G35: 23000 | I35: Ресурс по оригиналу — уточнить | J35: =IF(AND($A35<>"",$A35=Подбор!$C$4),MAX(J$1:J34)+1,"")
A36: HP LaserJet Pro MFP M428fdn | B36: HP | C36: Драм-юнит | D36: — | E36: HB-CF219A | F36: HiBlack | G36: 23000 | I36: Ресурс по оригиналу — уточнить | J36: =IF(AND($A36<>"",$A36=Подбор!$C$4),MAX(J$1:J35)+1,"")
A37: HP LaserJet Pro MFP M428fdn | B37: HP | C37: Термоузел | D37: — | E37: CS-FU-HP-M428 | F37: Cactus | J37: =IF(AND($A37<>"",$A37=Подбор!$C$4),MAX(J$1:J36)+1,"")
A38: Toshiba e-STUDIO2505 | B38: Toshiba | C38: Тонер-картридж | D38: Black | E38: — | J38: =IF(AND($A38<>"",$A38=Подбор!$C$4),MAX(J$1:J37)+1,"")
A39: Toshiba e-STUDIO2505 | B39: Toshiba | C39: Драм-юнит | D39: — | E39: — | J39: =IF(AND($A39<>"",$A39=Подбор!$C$4),MAX(J$1:J38)+1,"")
A40: Toshiba e-STUDIO2505 | B40: Toshiba | C40: Девелопер | D40: — | E40: — | J40: =IF(AND($A40<>"",$A40=Подбор!$C$4),MAX(J$1:J39)+1,"")
...

Sheet Подбор
A1: Подбор расходных материалов по аппарату
A2: Жёлтые ячейки — для выбора из выпадающих списков. Остальное подтягивается автоматически из листов «Оригинал» и «Совместимая».
B3: Производитель | C3: Xerox
B4: Модель аппарата | C4: Xerox WorkCentre 7845
B5: =IF($C$4="","← выберите производителя и модель",IF(COUNTIF(Модели!$B:$B,$C$4)=0,"Модель не найдена в списке",IF(INDEX(Модели!$A:$A,MATCH($C$4,Модели!$B:$B,0))<>$C$3,"Модель не относится к выбранному производителю","Найдено: оригинал — "&COUNT($J$9:$J$20)&" поз., совместимые — "&COUNT($J$25:$J$36)&" поз."))) -> Найдено: оригинал — 8 поз., совместимые — 8 поз.
A7: ОРИГИНАЛЬНАЯ РАСХОДКА
A8: № | B8: Тип расходки | C8: Цвет | D8: Артикул | E8: Бренд | F8: Ресурс стр. | G8: Цена | H8: Примечание | J8: Строка в базе
A9: =IF($J9="","",ROWS($A$9:A9)) -> 1 | B9: =IF($J9="","",IF(INDEX(Оригинал!$C:$C,$J9)="","",INDEX(Оригинал!$C:$C,$J9))) -> Тонер-картридж | C9: =IF($J9="","",IF(INDEX(Оригинал!$D:$D,$J9)="","",INDEX(Оригинал!$D:$D,$J9))) -> Black | D9: =IF($J9="","",IF(INDEX(Оригинал!$E:$E,$J9)="","⚠ добавить артикул",INDEX(Оригинал!$E:$E,$J9))) -> 006R01517 | E9: =IF($J9="","",IF(INDEX(Оригинал!$B:$B,$J9)="","",INDEX(Оригинал!$B:$B,$J9))) -> Xerox | F9: =IF($J9="","",IF(INDEX(Оригинал!$F:$F,$J9)="","",INDEX(Оригинал!$F:$F,$J9))) -> 26000 | G9: =IF($J9="","",IF(INDEX(Оригинал!$G:$G,$J9)="","",INDEX(Оригинал!$G:$G,$J9))) | H9: =IF($J9="","",IF(INDEX(Оригинал!$H:$H,$J9)="","",INDEX(Оригинал!$H:$H,$J9))) | J9: =IFERROR(MATCH(ROWS($J$9:J9),Оригинал!$I:$I,0),"") -> 5
A10: =IF($J10="","",ROWS($A$9:A10)) -> 2 | B10: =IF($J10="","",IF(INDEX(Оригинал!$C:$C,$J10)="","",INDEX(Оригинал!$C:$C,$J10))) -> Тонер-картридж | C10: =IF($J10="","",IF(INDEX(Оригинал!$D:$D,$J10)="","",INDEX(Оригинал!$D:$D,$J10))) -> Cyan | D10: =IF($J10="","",IF(INDEX(Оригинал!$E:$E,$J10)="","⚠ добавить артикул",INDEX(Оригинал!$E:$E,$J10))) -> 006R01520 | E10: =IF($J10="","",IF(INDEX(Оригинал!$B:$B,$J10)="","",INDEX(Оригинал!$B:$B,$J10))) -> Xerox | F10: =IF($J10="","",IF(INDEX(Оригинал!$F:$F,$J10)="","",INDEX(Оригинал!$F:$F,$J10))) -> 15000 | G10: =IF($J10="","",IF(INDEX(Оригинал!$G:$G,$J10)="","",INDEX(Оригинал!$G:$G,$J10))) | H10: =IF($J10="","",IF(INDEX(Оригинал!$H:$H,$J10)="","",INDEX(Оригинал!$H:$H,$J10))) | J10: =IFERROR(MATCH(ROWS($J$9:J10),Оригинал!$I:$I,0),"") -> 6
A11: =IF($J11="","",ROWS($A$9:A11)) -> 3 | B11: =IF($J11="","",IF(INDEX(Оригинал!$C:$C,$J11)="","",INDEX(Оригинал!$C:$C,$J11))) -> Тонер-картридж | C11: =IF($J11="","",IF(INDEX(Оригинал!$D:$D,$J11)="","",INDEX(Оригинал!$D:$D,$J11))) -> Magenta | D11: =IF($J11="","",IF(INDEX(Оригинал!$E:$E,$J11)="","⚠ добавить артикул",INDEX(Оригинал!$E:$E,$J11))) -> 006R01519 | E11: =IF($J11="","",IF(INDEX(Оригинал!$B:$B,$J11)="","",INDEX(Оригинал!$B:$B,$J11))) -> Xerox | F11: =IF($J11="","",IF(INDEX(Оригинал!$F:$F,$J11)="","",INDEX(Оригинал!$F:$F,$J11))) -> 15000 | G11: =IF($J11="","",IF(INDEX(Оригинал!$G:$G,$J11)="","",INDEX(Оригинал!$G:$G,$J11))) | H11: =IF($J11="","",IF(INDEX(Оригинал!$H:$H,$J11)="","",INDEX(Оригинал!$H:$H,$J11))) | J11: =IFERROR(MATCH(ROWS($J$9:J11),Оригинал!$I:$I,0),"") -> 7
A12: =IF($J12="","",ROWS($A$9:A12)) -> 4 | B12: =IF($J12="","",IF(INDEX(Оригинал!$C:$C,$J12)="","",INDEX(Оригинал!$C:$C,$J12))) -> Тонер-картридж | C12: =IF($J12="","",IF(INDEX(Оригинал!$D:$D,$J12)="","",INDEX(Оригинал!$D:$D,$J12))) -> Yellow | D12: =IF($J12="","",IF(INDEX(Оригинал!$E:$E,$J12)="","⚠ добавить артикул",INDEX(Оригинал!$E:$E,$J12))) -> 006R01518 | E12: =IF($J12="","",IF(INDEX(Оригинал!$B:$B,$J12)="","",INDEX(Оригинал!$B:$B,$J12))) -> Xerox | F12: =IF($J12="","",IF(INDEX(Оригинал!$F:$F,$J12)="","",INDEX(Оригинал!$F:$F,$J12))) -> 15000 | G12: =IF($J12="","",IF(INDEX(Оригинал!$G:$G,$J12)="","",INDEX(Оригинал!$G:$G,$J12))) | H12: =IF($J12="","",IF(INDEX(Оригинал!$H:$H,$J12)="","",INDEX(Оригинал!$H:$H,$J12))) | J12: =IFERROR(MATCH(ROWS($J$9:J12),Оригинал!$I:$I,0),"") -> 8
A13: =IF($J13="","",ROWS($A$9:A13)) -> 5 | B13: =IF($J13="","",IF(INDEX(Оригинал!$C:$C,$J13)="","",INDEX(Оригинал!$C:$C,$J13))) -> Драм-юнит | C13: =IF($J13="","",IF(INDEX(Оригинал!$D:$D,$J13)="","",INDEX(Оригинал!$D:$D,$J13))) -> — | D13: =IF($J13="","",IF(INDEX(Оригинал!$E:$E,$J13)="","⚠ добавить артикул",INDEX(Оригинал!$E:$E,$J13))) -> 013R00662 | E13: =IF($J13="","",IF(INDEX(Оригинал!$B:$B,$J13)="","",INDEX(Оригинал!$B:$B,$J13))) -> Xerox | F13: =IF($J13="","",IF(INDEX(Оригинал!$F:$F,$J13)="","",INDEX(Оригинал!$F:$F,$J13))) -> 125000 | G13: =IF($J13="","",IF(INDEX(Оригинал!$G:$G,$J13)="","",INDEX(Оригинал!$G:$G,$J13))) | H13: =IF($J13="","",IF(INDEX(Оригинал!$H:$H,$J13)="","",INDEX(Оригинал!$H:$H,$J13))) | J13: =IFERROR(MATCH(ROWS($J$9:J13),Оригинал!$I:$I,0),"") -> 9
A14: =IF($J14="","",ROWS($A$9:A14)) -> 6 | B14: =IF($J14="","",IF(INDEX(Оригинал!$C:$C,$J14)="","",INDEX(Оригинал!$C:$C,$J14))) -> Блок проявки | C14: =IF($J14="","",IF(INDEX(Оригинал!$D:$D,$J14)="","",INDEX(Оригинал!$D:$D,$J14))) -> — | D14: =IF($J14="","",IF(INDEX(Оригинал!$E:$E,$J14)="","⚠ добавить артикул",INDEX(Оригинал!$E:$E,$J14))) -> 848K65672 | E14: =IF($J14="","",IF(INDEX(Оригинал!$B:$B,$J14)="","",INDEX(Оригинал!$B:$B,$J14))) -> Xerox | F14: =IF($J14="","",IF(INDEX(Оригинал!$F:$F,$J14)="","",INDEX(Оригинал!$F:$F,$J14))) | G14: =IF($J14="","",IF(INDEX(Оригинал!$G:$G,$J14)="","",INDEX(Оригинал!$G:$G,$J14))) | H14: =IF($J14="","",IF(INDEX(Оригинал!$H:$H,$J14)="","",INDEX(Оригинал!$H:$H,$J14))) | J14: =IFERROR(MATCH(ROWS($J$9:J14),Оригинал!$I:$I,0),"") -> 10
A15: =IF($J15="","",ROWS($A$9:A15)) -> 7 | B15: =IF($J15="","",IF(INDEX(Оригинал!$C:$C,$J15)="","",INDEX(Оригинал!$C:$C,$J15))) -> Бункер отработки | C15: =IF($J15="","",IF(INDEX(Оригинал!$D:$D,$J15)="","",INDEX(Оригинал!$D:$D,$J15))) -> — | D15: =IF($J15="","",IF(INDEX(Оригинал!$E:$E,$J15)="","⚠ добавить артикул",INDEX(Оригинал!$E:$E,$J15))) -> 008R13061 | E15: =IF($J15="","",IF(INDEX(Оригинал!$B:$B,$J15)="","",INDEX(Оригинал!$B:$B,$J15))) -> Xerox | F15: =IF($J15="","",IF(INDEX(Оригинал!$F:$F,$J15)="","",INDEX(Оригинал!$F:$F,$J15))) | G15: =IF($J15="","",IF(INDEX(Оригинал!$G:$G,$J15)="","",INDEX(Оригинал!$G:$G,$J15))) | H15: =IF($J15="","",IF(INDEX(Оригинал!$H:$H,$J15)="","",INDEX(Оригинал!$H:$H,$J15))) | J15: =IFERROR(MATCH(ROWS($J$9:J15),Оригинал!$I:$I,0),"") -> 11
A16: =IF($J16="","",ROWS($A$9:A16)) -> 8 | B16: =IF($J16="","",IF(INDEX(Оригинал!$C:$C,$J16)="","",INDEX(Оригинал!$C:$C,$J16))) -> Термоузел | C16: =IF($J16="","",IF(INDEX(Оригинал!$D:$D,$J16)="","",INDEX(Оригинал!$D:$D,$J16))) -> — | D16: =IF($J16="","",IF(INDEX(Оригинал!$E:$E,$J16)="","⚠ добавить артикул",INDEX(Оригинал!$E:$E,$J16))) -> 604K62230 | E16: =IF($J16="","",IF(INDEX(Оригинал!$B:$B,$J16)="","",INDEX(Оригинал!$B:$B,$J16))) -> Xerox | F16: =IF($J16="","",IF(INDEX(Оригинал!$F:$F,$J16)="","",INDEX(Оригинал!$F:$F,$J16))) | G16: =IF($J16="","",IF(INDEX(Оригинал!$G:$G,$J16)="","",INDEX(Оригинал!$G:$G,$J16))) | H16: =IF($J16="","",IF(INDEX(Оригинал!$H:$H,$J16)="","",INDEX(Оригинал!$H:$H,$J16))) | J16: =IFERROR(MATCH(ROWS($J$9:J16),Оригинал!$I:$I,0),"") -> 12
A17: =IF($J17="","",ROWS($A$9:A17)) | B17: =IF($J17="","",IF(INDEX(Оригинал!$C:$C,$J17)="","",INDEX(Оригинал!$C:$C,$J17))) | C17: =IF($J17="","",IF(INDEX(Оригинал!$D:$D,$J17)="","",INDEX(Оригинал!$D:$D,$J17))) | D17: =IF($J17="","",IF(INDEX(Оригинал!$E:$E,$J17)="","⚠ добавить артикул",INDEX(Оригинал!$E:$E,$J17))) | E17: =IF($J17="","",IF(INDEX(Оригинал!$B:$B,$J17)="","",INDEX(Оригинал!$B:$B,$J17))) | F17: =IF($J17="","",IF(INDEX(Оригинал!$F:$F,$J17)="","",INDEX(Оригинал!$F:$F,$J17))) | G17: =IF($J17="","",IF(INDEX(Оригинал!$G:$G,$J17)="","",INDEX(Оригинал!$G:$G,$J17))) | H17: =IF($J17="","",IF(INDEX(Оригинал!$H:$H,$J17)="","",INDEX(Оригинал!$H:$H,$J17))) | J17: =IFERROR(MATCH(ROWS($J$9:J17),Оригинал!$I:$I,0),"")
A18: =IF($J18="","",ROWS($A$9:A18)) | B18: =IF($J18="","",IF(INDEX(Оригинал!$C:$C,$J18)="","",INDEX(Оригинал!$C:$C,$J18))) | C18: =IF($J18="","",IF(INDEX(Оригинал!$D:$D,$J18)="","",INDEX(Оригинал!$D:$D,$J18))) | D18: =IF($J18="","",IF(INDEX(Оригинал!$E:$E,$J18)="","⚠ добавить артикул",INDEX(Оригинал!$E:$E,$J18))) | E18: =IF($J18="","",IF(INDEX(Оригинал!$B:$B,$J18)="","",INDEX(Оригинал!$B:$B,$J18))) | F18: =IF($J18="","",IF(INDEX(Оригинал!$F:$F,$J18)="","",INDEX(Оригинал!$F:$F,$J18))) | G18: =IF($J18="","",IF(INDEX(Оригинал!$G:$G,$J18)="","",INDEX(Оригинал!$G:$G,$J18))) | H18: =IF($J18="","",IF(INDEX(Оригинал!$H:$H,$J18)="","",INDEX(Оригинал!$H:$H,$J18))) | J18: =IFERROR(MATCH(ROWS($J$9:J18),Оригинал!$I:$I,0),"")
A19: =IF($J19="","",ROWS($A$9:A19)) | B19: =IF($J19="","",IF(INDEX(Оригинал!$C:$C,$J19)="","",INDEX(Оригинал!$C:$C,$J19))) | C19: =IF($J19="","",IF(INDEX(Оригинал!$D:$D,$J19)="","",INDEX(Оригинал!$D:$D,$J19))) | D19: =IF($J19="","",IF(INDEX(Оригинал!$E:$E,$J19)="","⚠ добавить артикул",INDEX(Оригинал!$E:$E,$J19))) | E19: =IF($J19="","",IF(INDEX(Оригинал!$B:$B,$J19)="","",INDEX(Оригинал!$B:$B,$J19))) | F19: =IF($J19="","",IF(INDEX(Оригинал!$F:$F,$J19)="","",INDEX(Оригинал!$F:$F,$J19))) | G19: =IF($J19="","",IF(INDEX(Оригинал!$G:$G,$J19)="","",INDEX(Оригинал!$G:$G,$J19))) | H19: =IF($J19="","",IF(INDEX(Оригинал!$H:$H,$J19)="","",INDEX(Оригинал!$H:$H,$J19))) | J19: =IFERROR(MATCH(ROWS($J$9:J19),Оригинал!$I:$I,0),"")
A20: =IF($J20="","",ROWS($A$9:A20)) | B20: =IF($J20="","",IF(INDEX(Оригинал!$C:$C,$J20)="","",INDEX(Оригинал!$C:$C,$J20))) | C20: =IF($J20="","",IF(INDEX(Оригинал!$D:$D,$J20)="","",INDEX(Оригинал!$D:$D,$J20))) | D20: =IF($J20="","",IF(INDEX(Оригинал!$E:$E,$J20)="","⚠ добавить артикул",INDEX(Оригинал!$E:$E,$J20))) | E20: =IF($J20="","",IF(INDEX(Оригинал!$B:$B,$J20)="","",INDEX(Оригинал!$B:$B,$J20))) | F20: =IF($J20="","",IF(INDEX(Оригинал!$F:$F,$J20)="","",INDEX(Оригинал!$F:$F,$J20))) | G20: =IF($J20="","",IF(INDEX(Оригинал!$G:$G,$J20)="","",INDEX(Оригинал!$G:$G,$J20))) | H20: =IF($J20="","",IF(INDEX(Оригинал!$H:$H,$J20)="","",INDEX(Оригинал!$H:$H,$J20))) | J20: =IFERROR(MATCH(ROWS($J$9:J20),Оригинал!$I:$I,0),"")
A23: СОВМЕСТИМАЯ РАСХОДКА
A24: № | B24: Тип расходки | C24: Цвет | D24: Артикул | E24: Бренд | F24: Ресурс стр. | G24: Цена | H24: Примечание | J24: Строка в базе
A25: =IF($J25="","",ROWS($A$25:A25)) -> 1 | B25: =IF($J25="","",IF(INDEX(Совместимая!$C:$C,$J25)="","",INDEX(Совместимая!$C:$C,$J25))) -> Тонер-картридж | C25: =IF($J25="","",IF(INDEX(Совместимая!$D:$D,$J25)="","",INDEX(Совместимая!$D:$D,$J25))) -> Black | D25: =IF($J25="","",IF(INDEX(Совместимая!$E:$E,$J25)="","⚠ добавить артикул",INDEX(Совместимая!$E:$E,$J25))) -> CS-WC7525BK | E25: =IF($J25="","",IF(INDEX(Совместимая!$F:$F,$J25)="","",INDEX(Совместимая!$F:$F,$J25))) -> Cactus | F25: =IF($J25="","",IF(INDEX(Совместимая!$G:$G,$J25)="","",INDEX(Совместимая!$G:$G,$J25))) | G25: =IF($J25="","",IF(INDEX(Совместимая!$H:$H,$J25)="","",INDEX(Совместимая!$H:$H,$J25))) | H25: =IF($J25="","",IF(INDEX(Совместимая!$I:$I,$J25)="","",INDEX(Совместимая!$I:$I,$J25))) | J25: =IFERROR(MATCH(ROWS($J$25:J25),Совместимая!$J:$J,0),"") -> 5
A26: =IF($J26="","",ROWS($A$25:A26)) -> 2 | B26: =IF($J26="","",IF(INDEX(Совместимая!$C:$C,$J26)="","",INDEX(Совместимая!$C:$C,$J26))) -> Тонер-картридж | C26: =IF($J26="","",IF(INDEX(Совместимая!$D:$D,$J26)="","",INDEX(Совместимая!$D:$D,$J26))) -> Cyan | D26: =IF($J26="","",IF(INDEX(Совместимая!$E:$E,$J26)="","⚠ добавить артикул",INDEX(Совместимая!$E:$E,$J26))) -> CS-WC7525C | E26: =IF($J26="","",IF(INDEX(Совместимая!$F:$F,$J26)="","",INDEX(Совместимая!$F:$F,$J26))) -> Cactus | F26: =IF($J26="","",IF(INDEX(Совместимая!$G:$G,$J26)="","",INDEX(Совместимая!$G:$G,$J26))) | G26: =IF($J26="","",IF(INDEX(Совместимая!$H:$H,$J26)="","",INDEX(Совместимая!$H:$H,$J26))) | H26: =IF($J26="","",IF(INDEX(Совместимая!$I:$I,$J26)="","",INDEX(Совместимая!$I:$I,$J26))) | J26: =IFERROR(MATCH(ROWS($J$25:J26),Совместимая!$J:$J,0),"") -> 6
A27: =IF($J27="","",ROWS($A$25:A27)) -> 3 | B27: =IF($J27="","",IF(INDEX(Совместимая!$C:$C,$J27)="","",INDEX(Совместимая!$C:$C,$J27))) -> Тонер-картридж | C27: =IF($J27="","",IF(INDEX(Совместимая!$D:$D,$J27)="","",INDEX(Совместимая!$D:$D,$J27))) -> Magenta | D27: =IF($J27="","",IF(INDEX(Совместимая!$E:$E,$J27)="","⚠ добавить артикул",INDEX(Совместимая!$E:$E,$J27))) -> CS-WC7525M | E27: =IF($J27="","",IF(INDEX(Совместимая!$F:$F,$J27)="","",INDEX(Совместимая!$F:$F,$J27))) -> Cactus | F27: =IF($J27="","",IF(INDEX(Совместимая!$G:$G,$J27)="","",INDEX(Совместимая!$G:$G,$J27))) | G27: =IF($J27="","",IF(INDEX(Совместимая!$H:$H,$J27)="","",INDEX(Совместимая!$H:$H,$J27))) | H27: =IF($J27="","",IF(INDEX(Совместимая!$I:$I,$J27)="","",INDEX(Совместимая!$I:$I,$J27))) | J27: =IFERROR(MATCH(ROWS($J$25:J27),Совместимая!$J:$J,0),"") -> 7
A28: =IF($J28="","",ROWS($A$25:A28)) -> 4 | B28: =IF($J28="","",IF(INDEX(Совместимая!$C:$C,$J28)="","",INDEX(Совместимая!$C:$C,$J28))) -> Тонер-картридж | C28: =IF($J28="","",IF(INDEX(Совместимая!$D:$D,$J28)="","",INDEX(Совместимая!$D:$D,$J28))) -> Yellow | D28: =IF($J28="","",IF(INDEX(Совместимая!$E:$E,$J28)="","⚠ добавить артикул",INDEX(Совместимая!$E:$E,$J28))) -> CS-WC7525Y | E28: =IF($J28="","",IF(INDEX(Совместимая!$F:$F,$J28)="","",INDEX(Совместимая!$F:$F,$J28))) -> Cactus | F28: =IF($J28="","",IF(INDEX(Совместимая!$G:$G,$J28)="","",INDEX(Совместимая!$G:$G,$J28))) | G28: =IF($J28="","",IF(INDEX(Совместимая!$H:$H,$J28)="","",INDEX(Совместимая!$H:$H,$J28))) | H28: =IF($J28="","",IF(INDEX(Совместимая!$I:$I,$J28)="","",INDEX(Совместимая!$I:$I,$J28))) | J28: =IFERROR(MATCH(ROWS($J$25:J28),Совместимая!$J:$J,0),"") -> 8
A29: =IF($J29="","",ROWS($A$25:A29)) -> 5 | B29: =IF($J29="","",IF(INDEX(Совместимая!$C:$C,$J29)="","",INDEX(Совместимая!$C:$C,$J29))) -> Драм-юнит | C29: =IF($J29="","",IF(INDEX(Совместимая!$D:$D,$J29)="","",INDEX(Совместимая!$D:$D,$J29))) -> — | D29: =IF($J29="","",IF(INDEX(Совместимая!$E:$E,$J29)="","⚠ добавить артикул",INDEX(Совместимая!$E:$E,$J29))) -> CS-DU7525 | E29: =IF($J29="","",IF(INDEX(Совместимая!$F:$F,$J29)="","",INDEX(Совместимая!$F:$F,$J29))) -> Cactus | F29: =IF($J29="","",IF(INDEX(Совместимая!$G:$G,$J29)="","",INDEX(Совместимая!$G:$G,$J29))) | G29: =IF($J29="","",IF(INDEX(Совместимая!$H:$H,$J29)="","",INDEX(Совместимая!$H:$H,$J29))) | H29: =IF($J29="","",IF(INDEX(Совместимая!$I:$I,$J29)="","",INDEX(Совместимая!$I:$I,$J29))) | J29: =IFERROR(MATCH(ROWS($J$25:J29),Совместимая!$J:$J,0),"") -> 9
A30: =IF($J30="","",ROWS($A$25:A30)) -> 6 | B30: =IF($J30="","",IF(INDEX(Совместимая!$C:$C,$J30)="","",INDEX(Совместимая!$C:$C,$J30))) -> Блок проявки | C30: =IF($J30="","",IF(INDEX(Совместимая!$D:$D,$J30)="","",INDEX(Совместимая!$D:$D,$J30))) -> — | D30: =IF($J30="","",IF(INDEX(Совместимая!$E:$E,$J30)="","⚠ добавить артикул",INDEX(Совместимая!$E:$E,$J30))) -> CS-DU7525RU | E30: =IF($J30="","",IF(INDEX(Совместимая!$F:$F,$J30)="","",INDEX(Совместимая!$F:$F,$J30))) -> Cactus | F30: =IF($J30="","",IF(INDEX(Совместимая!$G:$G,$J30)="","",INDEX(Совместимая!$G:$G,$J30))) | G30: =IF($J30="","",IF(INDEX(Совместимая!$H:$H,$J30)="","",INDEX(Совместимая!$H:$H,$J30))) | H30: =IF($J30="","",IF(INDEX(Совместимая!$I:$I,$J30)="","",INDEX(Совместимая!$I:$I,$J30))) | J30: =IFERROR(MATCH(ROWS($J$25:J30),Совместимая!$J:$J,0),"") -> 10
A31: =IF($J31="","",ROWS($A$25:A31)) -> 7 | B31: =IF($J31="","",IF(INDEX(Совместимая!$C:$C,$J31)="","",INDEX(Совместимая!$C:$C,$J31))) -> Бункер отработки | C31: =IF($J31="","",IF(INDEX(Совместимая!$D:$D,$J31)="","",INDEX(Совместимая!$D:$D,$J31))) -> — | D31: =IF($J31="","",IF(INDEX(Совместимая!$E:$E,$J31)="","⚠ добавить артикул",INDEX(Совместимая!$E:$E,$J31))) -> CS-WB7425 | E31: =IF($J31="","",IF(INDEX(Совместимая!$F:$F,$J31)="","",INDEX(Совместимая!$F:$F,$J31))) -> Cactus | F31: =IF($J31="","",IF(INDEX(Совместимая!$G:$G,$J31)="","",INDEX(Совместимая!$G:$G,$J31))) | G31: =IF($J31="","",IF(INDEX(Совместимая!$H:$H,$J31)="","",INDEX(Совместимая!$H:$H,$J31))) | H31: =IF($J31="","",IF(INDEX(Совместимая!$I:$I,$J31)="","",INDEX(Совместимая!$I:$I,$J31))) | J31: =IFERROR(MATCH(ROWS($J$25:J31),Совместимая!$J:$J,0),"") -> 11
A32: =IF($J32="","",ROWS($A$25:A32)) -> 8 | B32: =IF($J32="","",IF(INDEX(Совместимая!$C:$C,$J32)="","",INDEX(Совместимая!$C:$C,$J32))) -> Термоузел | C32: =IF($J32="","",IF(INDEX(Совместимая!$D:$D,$J32)="","",INDEX(Совместимая!$D:$D,$J32))) -> — | D32: =IF($J32="","",IF(INDEX(Совместимая!$E:$E,$J32)="","⚠ добавить артикул",INDEX(Совместимая!$E:$E,$J32))) -> CS-FU-XER-WC7545 | E32: =IF($J32="","",IF(INDEX(Совместимая!$F:$F,$J32)="","",INDEX(Совместимая!$F:$F,$J32))) -> Cactus | F32: =IF($J32="","",IF(INDEX(Совместимая!$G:$G,$J32)="","",INDEX(Совместимая!$G:$G,$J32))) | G32: =IF($J32="","",IF(INDEX(Совместимая!$H:$H,$J32)="","",INDEX(Совместимая!$H:$H,$J32))) | H32: =IF($J32="","",IF(INDEX(Совместимая!$I:$I,$J32)="","",INDEX(Совместимая!$I:$I,$J32))) | J32: =IFERROR(MATCH(ROWS($J$25:J32),Совместимая!$J:$J,0),"") -> 12
A33: =IF($J33="","",ROWS($A$25:A33)) | B33: =IF($J33="","",IF(INDEX(Совместимая!$C:$C,$J33)="","",INDEX(Совместимая!$C:$C,$J33))) | C33: =IF($J33="","",IF(INDEX(Совместимая!$D:$D,$J33)="","",INDEX(Совместимая!$D:$D,$J33))) | D33: =IF($J33="","",IF(INDEX(Совместимая!$E:$E,$J33)="","⚠ добавить артикул",INDEX(Совместимая!$E:$E,$J33))) | E33: =IF($J33="","",IF(INDEX(Совместимая!$F:$F,$J33)="","",INDEX(Совместимая!$F:$F,$J33))) | F33: =IF($J33="","",IF(INDEX(Совместимая!$G:$G,$J33)="","",INDEX(Совместимая!$G:$G,$J33))) | G33: =IF($J33="","",IF(INDEX(Совместимая!$H:$H,$J33)="","",INDEX(Совместимая!$H:$H,$J33))) | H33: =IF($J33="","",IF(INDEX(Совместимая!$I:$I,$J33)="","",INDEX(Совместимая!$I:$I,$J33))) | J33: =IFERROR(MATCH(ROWS($J$25:J33),Совместимая!$J:$J,0),"")
A34: =IF($J34="","",ROWS($A$25:A34)) | B34: =IF($J34="","",IF(INDEX(Совместимая!$C:$C,$J34)="","",INDEX(Совместимая!$C:$C,$J34))) | C34: =IF($J34="","",IF(INDEX(Совместимая!$D:$D,$J34)="","",INDEX(Совместимая!$D:$D,$J34))) | D34: =IF($J34="","",IF(INDEX(Совместимая!$E:$E,$J34)="","⚠ добавить артикул",INDEX(Совместимая!$E:$E,$J34))) | E34: =IF($J34="","",IF(INDEX(Совместимая!$F:$F,$J34)="","",INDEX(Совместимая!$F:$F,$J34))) | F34: =IF($J34="","",IF(INDEX(Совместимая!$G:$G,$J34)="","",INDEX(Совместимая!$G:$G,$J34))) | G34: =IF($J34="","",IF(INDEX(Совместимая!$H:$H,$J34)="","",INDEX(Совместимая!$H:$H,$J34))) | H34: =IF($J34="","",IF(INDEX(Совместимая!$I:$I,$J34)="","",INDEX(Совместимая!$I:$I,$J34))) | J34: =IFERROR(MATCH(ROWS($J$25:J34),Совместимая!$J:$J,0),"")
A35: =IF($J35="","",ROWS($A$25:A35)) | B35: =IF($J35="","",IF(INDEX(Совместимая!$C:$C,$J35)="","",INDEX(Совместимая!$C:$C,$J35))) | C35: =IF($J35="","",IF(INDEX(Совместимая!$D:$D,$J35)="","",INDEX(Совместимая!$D:$D,$J35))) | D35: =IF($J35="","",IF(INDEX(Совместимая!$E:$E,$J35)="","⚠ добавить артикул",INDEX(Совместимая!$E:$E,$J35))) | E35: =IF($J35="","",IF(INDEX(Совместимая!$F:$F,$J35)="","",INDEX(Совместимая!$F:$F,$J35))) | F35: =IF($J35="","",IF(INDEX(Совместимая!$G:$G,$J35)="","",INDEX(Совместимая!$G:$G,$J35))) | G35: =IF($J35="","",IF(INDEX(Совместимая!$H:$H,$J35)="","",INDEX(Совместимая!$H:$H,$J35))) | H35: =IF($J35="","",IF(INDEX(Совместимая!$I:$I,$J35)="","",INDEX(Совместимая!$I:$I,$J35))) | J35: =IFERROR(MATCH(ROWS($J$25:J35),Совместимая!$J:$J,0),"")
A36: =IF($J36="","",ROWS($A$25:A36)) | B36: =IF($J36="","",IF(INDEX(Совместимая!$C:$C,$J36)="","",INDEX(Совместимая!$C:$C,$J36))) | C36: =IF($J36="","",IF(INDEX(Совместимая!$D:$D,$J36)="","",INDEX(Совместимая!$D:$D,$J36))) | D36: =IF($J36="","",IF(INDEX(Совместимая!$E:$E,$J36)="","⚠ добавить артикул",INDEX(Совместимая!$E:$E,$J36))) | E36: =IF($J36="","",IF(INDEX(Совместимая!$F:$F,$J36)="","",INDEX(Совместимая!$F:$F,$J36))) | F36: =IF($J36="","",IF(INDEX(Совместимая!$G:$G,$J36)="","",INDEX(Совместимая!$G:$G,$J36))) | G36: =IF($J36="","",IF(INDEX(Совместимая!$H:$H,$J36)="","",INDEX(Совместимая!$H:$H,$J36))) | H36: =IF($J36="","",IF(INDEX(Совместимая!$I:$I,$J36)="","",INDEX(Совместимая!$I:$I,$J36))) | J36: =IFERROR(MATCH(ROWS($J$25:J36),Совместимая!$J:$J,0),"")
A38: ⚠ на оранжевом фоне — позиция есть в другой базе, но артикул пока не найден: впишите его прямо в строку на листе «Оригинал» / «Совместимая».

Sheet Модели
A1: Производитель | B1: Модель аппарата | D1: Список производителей | E1: Моделей | G1: Служебный лист: списки для выпадающих меню на листе «Подбор». Объединение моделей из обеих баз. Новую модель добавляйте в конец списка и отсортируйте по колонке A (производитель).
A2: Avision | B2: Avision AM 76x0i | D2: Avision | E2: =COUNTIF($A$2:$A$785,D2) -> 2
A3: Avision | B3: Avision AM7640i | D3: Brother | E3: =COUNTIF($A$2:$A$785,D3) -> 12
A4: Brother | B4: Brother DCP-7010R | D4: Canon | E4: =COUNTIF($A$2:$A$785,D4) -> 88
A5: Brother | B5: Brother DCP-7057R | D5: Datamax | E5: =COUNTIF($A$2:$A$785,D5) -> 2
A6: Brother | B6: Brother DCP-L2500DR | D6: Epson | E6: =COUNTIF($A$2:$A$785,D6) -> 14
A7: Brother | B7: Brother DCP-L5500DN | D7: F+ | E7: =COUNTIF($A$2:$A$785,D7) -> 1
A8: Brother | B8: Brother DCP-L6600DW | D8: HP | E8: =COUNTIF($A$2:$A$785,D8) -> 350
A9: Brother | B9: Brother HL-1202R | D9: Konica Minolta | E9: =COUNTIF($A$2:$A$785,D9) -> 7
A10: Brother | B10: Brother HL-L2300DR | D10: Kyocera | E10: =COUNTIF($A$2:$A$785,D10) -> 92
A11: Brother | B11: Brother MFC-8370DN | D11: Lexmark | E11: =COUNTIF($A$2:$A$785,D11) -> 30
A12: Brother | B12: Brother MFC-8880DN | D12: Oki | E12: =COUNTIF($A$2:$A$785,D12) -> 5
A13: Brother | B13: Brother MFC-L3770CDW | D13: Panasonic | E13: =COUNTIF($A$2:$A$785,D13) -> 7
... A23: Canon | B23: Canon i-Sensys LBP6020 | D23: Катюша | E23: =COUNTIF($A$2:$A$785,D23) -> 4
A24: Canon | B24: Canon i-Sensys LBP612C
A25: Canon | B25: Canon i-Sensys LBP6780
A26: Canon | B26: Canon i-Sensys LBP7200C
A27: Canon | B27: Canon i-Sensys LBP7210cdn
A28: Canon | B28: Canon i-Sensys LBP7660C
A29: Canon | B29: Canon i-Sensys MF211
A30: Canon | B30: Canon i-Sensys MF249dw
A31: Canon | B31: Canon i-Sensys MF3010
A32: Canon | B32: Canon i-Sensys MF4010
A33: Canon | B33: Canon i-Sensys MF4018
A34: Canon | B34: Canon i-Sensys MF4100
A35: Canon | B35: Canon i-Sensys MF411dw
... A785: Катюша | B785: Катюша М247e
